Workbook

Sheet Read me
A1: Parity Medic · judging workbook
A2: Generated by Ari in cfo.ai · 12 October 2026 · USD
A3: No verified customers or funding. $5,000 starting cash is hypothetical.
A4: No existing company records or integrations used or changed.
A5: Native export formulas remain on the PM worksheets and Model inputs.
A6: Main = 0 accounts; compared scenarios = 100 and 500 accounts.
A7: Repair cases and Pricing cases are static snapshots of all native-engine scenarios.
A8: Runway is blank in native formulas for non-burning cases; see status rows.
A9: Full costs include a hypothetical 20% reserve on positive pre-tax cash operating profit.
A10: One-time validation = $1,500, deducted in the cash projection, not recurring burn.
A11: Economic profit also charges unpaid founder time; not a jurisdiction-specific tax forecast.
A12: Steady-state cases exclude initial customer acquisition. Indicative CAC capital needs:
... A17: Canvas is interactive/read-only in cfo.ai; this workbook includes report prose but not Canvas.

Sheet PM Hypothetical assumptions
A1: PM Hypothetical assumptions
A2: Parity Medic · neatHack business plan · Main Scenario
A4: Variable / dimension | B4: Value
A5: PM Customers | B5: =0 -> 0
A6: PM Team share | B6: =0.2 -> 0.2
A7: PM Individual price | B7: =19 -> 19
A8: PM Team price | B8: =99 -> 99
A9: PM Individual repair cap | B9: =20 -> 20
A10: PM Team repair cap | B10: =100 -> 100
A11: PM Stress repairs per customer | B11: =100 -> 100
A12: PM Repair cost | B12: =0.05 -> 0.05
A13: PM Starting cash hypothetical | B13: =5000 -> 5000
A14: PM Validation budget | B14: =SUM('PM Validation budget'!B5,'PM Validation budget'!B6,'PM Validation budget'!B7,'PM Validation budget'!B8,'PM Validation budget'!B9,'PM Validation budget'!B10) -> 1500
A15: PM Monthly churn | B15: =0.03 -> 0.03
A16: PM Payment percent | B16: =0.029 -> 0.029
A17: PM Payment fee | B17: =0.3 -> 0.3
A18: PM Support hourly cost | B18: =25 -> 25
A19: PM Local individual support hours | B19: =0.1 -> 0.1
A20: PM Local team support hours | B20: =0.4 -> 0.4
A21: PM Hosted individual support hours | B21: =0.15 -> 0.15
A22: PM Hosted team support hours | B22: =0.6 -> 0.6
A23: PM Local individual compute storage | B23: =0.25 -> 0.25
A24: PM Local team compute storage | B24: =0.75 -> 0.75
A25: PM Hosted individual compute storage | B25: =0.75 -> 0.75
A26: PM Hosted team compute storage | B26: =3 -> 3
A27: PM Local fixed delivery | B27: =25 -> 25
A28: PM Hosted fixed delivery | B28: =150 -> 150
A29: PM Local software | B29: =45 -> 45
A30: PM Hosted software | B30: =60 -> 60
A31: PM Local legal security reserve | B31: =75 -> 75
A32: PM Hosted legal security reserve | B32: =150 -> 150
A33: PM Local administration | B33: =30 -> 30
A34: PM Hosted administration | B34: =40 -> 40
A35: PM Local founder cash stipend | B35: =600 -> 600
A36: PM Hosted founder cash stipend | B36: =1000 -> 1000
A37: PM Local growth experiments | B37: =150 -> 150
A38: PM Hosted growth experiments | B38: =300 -> 300
A39: PM Local replacement CAC | B39: =40 -> 40
A40: PM Hosted replacement CAC | B40: =65 -> 65
A41: PM Founder fair monthly compensation | B41: =2500 -> 2500

Sheet PM Monthly economics
A1: PM Monthly economics
A2: Parity Medic · neatHack business plan · Main Scenario
A4: Variable / dimension | B4: Value | C4: Value > Parity Medic · 100 customers | D4: Value > Parity Medic · 500 customers
A5: PM Individuals | B5: ='PM Hypothetical assumptions'!B5*(1-'PM Hypothetical assumptions'!B6) -> 0 | C5: ='Model inputs'!B7*(1-'Model inputs'!B141) -> 80 | D5: ='Model inputs'!B8*(1-'Model inputs'!B142) -> 400
A6: PM Teams | B6: ='PM Hypothetical assumptions'!B5*'PM Hypothetical assumptions'!B6 -> 0 | C6: ='Model inputs'!B7*'Model inputs'!B141 -> 20 | D6: ='Model inputs'!B8*'Model inputs'!B142 -> 100
A7: PM ARPU | B7: ='PM Hypothetical assumptions'!B7*(1-'PM Hypothetical assumptions'!B6)+'PM Hypothetical assumptions'!B8*'PM Hypothetical assumptions'!B6 -> 35 | C7: ='Model inputs'!B60*(1-'Model inputs'!B141)+'Model inputs'!B135*'Model inputs'!B141 -> 35 | D7: ='Model inputs'!B61*(1-'Model inputs'!B142)+'Model inputs'!B136*'Model inputs'!B142 -> 35
A8: PM Included repairs per customer | B8: ='PM Hypothetical assumptions'!B9*(1-'PM Hypothetical assumptions'!B6)+'PM Hypothetical assumptions'!B10*'PM Hypothetical assumptions'!B6 -> 36 | C8: ='Model inputs'!B63*(1-'Model inputs'!B141)+'Model inputs'!B138*'Model inputs'!B141 -> 36 | D8: ='Model inputs'!B64*(1-'Model inputs'!B142)+'Model inputs'!B139*'Model inputs'!B142 -> 36
A9: PM MRR | B9: ='PM Hypothetical assumptions'!B5*'PM Monthly economics'!B7 -> 0 | C9: ='Model inputs'!B7*'PM Monthly economics'!C7 -> 3500 | D9: ='Model inputs'!B8*'PM Monthly economics'!D7 -> 17500
A10: PM Annualized revenue run rate | B10: ='PM Monthly economics'!B9*12 -> 0 | C10: ='PM Monthly economics'!C9*12 -> 42000 | D10: ='PM Monthly economics'!D9*12 -> 210000
A11: PM Replacement customers per month | B11: ='PM Hypothetical assumptions'!B5*'PM Hypothetical assumptions'!B15 -> 0 | C11: ='Model inputs'!B7*'Model inputs'!B114 -> 3 | D11: ='Model inputs'!B8*'Model inputs'!B115 -> 15
A12: PM Inference per customer | B12: ='PM Monthly economics'!B8*'PM Hypothetical assumptions'!B12 -> 1.8 | C12: ='PM Monthly economics'!C8*'Model inputs'!B123 -> 1.8 | D12: ='PM Monthly economics'!D8*'Model inputs'!B124 -> 1.8
A13: PM Payment per customer | B13: ='PM Monthly economics'!B7*'PM Hypothetical assumptions'!B16+'PM Hypothetical assumptions'!B17 -> 1.315 | C13: ='PM Monthly economics'!C7*'Model inputs'!B120+'Model inputs'!B117 -> 1.315 | D13: ='PM Monthly economics'!D7*'Model inputs'!B121+'Model inputs'!B118 -> 1.315
A14: PM Local support per customer | B14: =('PM Hypothetical assumptions'!B19*(1-'PM Hypothetical assumptions'!B6)+'PM Hypothetical assumptions'!B20*'PM Hypothetical assumptions'!B6)*'PM Hypothetical assumptions'!B18 -> 4 | C14: =('Model inputs'!B81*(1-'Model inputs'!B141)+'Model inputs'!B111*'Model inputs'!B141)*'Model inputs'!B132 -> 4 | D14: =('Model inputs'!B82*(1-'Model inputs'!B142)+'Model inputs'!B112*'Model inputs'!B142)*'Model inputs'!B133 -> 4
A15: PM Local compute storage per customer | B15: ='PM Hypothetical assumptions'!B23*(1-'PM Hypothetical assumptions'!B6)+'PM Hypothetical assumptions'!B24*'PM Hypothetical assumptions'!B6 -> 0.35 | C15: ='Model inputs'!B78*(1-'Model inputs'!B141)+'Model inputs'!B108*'Model inputs'!B141 -> 0.35 | D15: ='Model inputs'!B79*(1-'Model inputs'!B142)+'Model inputs'!B109*'Model inputs'!B142 -> 0.35
A16: PM Local variable cost per customer | B16: ='PM Monthly economics'!B12+'PM Monthly economics'!B13+'PM Monthly economics'!B14+'PM Monthly economics'!B15 -> 7.465 | C16: ='PM Monthly economics'!C12+'PM Monthly economics'!C13+'PM Monthly economics'!C14+'PM Monthly economics'!C15 -> 7.465 | D16: ='PM Monthly economics'!D12+'PM Monthly economics'!D13+'PM Monthly economics'!D14+'PM Monthly economics'!D15 -> 7.465
A17: PM Local contribution per customer | B17: ='PM Monthly economics'!B7-'PM Monthly economics'!B16 -> 27.535 | C17: ='PM Monthly economics'!C7-'PM Monthly economics'!C16 -> 27.535 | D17: ='PM Monthly economics'!D7-'PM Monthly economics'!D16 -> 27.535
A18: PM Local delivery COGS | B18: ='PM Hypothetical assumptions'!B5*'PM Monthly economics'!B16+'PM Hypothetical assumptions'!B27 -> 25 | C18: ='Model inputs'!B7*'PM Monthly economics'!C16+'Model inputs'!B69 -> 771.5 | D18: ='Model inputs'!B8*'PM Monthly economics'!D16+'Model inputs'!B70 -> 3757.5
A19: PM Local gross profit | B19: ='PM Monthly economics'!B9-'PM Monthly economics'!B18 -> -25 | C19: ='PM Monthly economics'!C9-'PM Monthly economics'!C18 -> 2728.5 | D19: ='PM Monthly economics'!D9-'PM Monthly economics'!D18 -> 13742.5
A20: PM Local gross margin | B20: =IFERROR('PM Monthly economics'!B19/'PM Monthly economics'!B9,"") | C20: =IFERROR('PM Monthly economics'!C19/'PM Monthly economics'!C9,"") -> 0.77957143 | D20: =IFERROR('PM Monthly economics'!D19/'PM Monthly economics'!D9,"") -> 0.78528571
A21: PM Local replacement acquisition | B21: ='PM Monthly economics'!B11*'PM Hypothetical assumptions'!B39 -> 0 | C21: ='PM Monthly economics'!C11*'Model inputs'!B102 -> 120 | D21: ='PM Monthly economics'!D11*'Model inputs'!B103 -> 600
A22: PM Local fixed operating cash | B22: ='PM Hypothetical assumptions'!B29+'PM Hypothetical assumptions'!B31+'PM Hypothetical assumptions'!B33+'PM Hypothetical assumptions'!B35+'PM Hypothetical assumptions'!B37 -> 900 | C22: ='Model inputs'!B105+'Model inputs'!B84+'Model inputs'!B66+'Model inputs'!B72+'Model inputs'!B75 -> 900 | D22: ='Model inputs'!B106+'Model inputs'!B85+'Model inputs'!B67+'Model inputs'!B73+'Model inputs'!B76 -> 900
A23: PM Local total monthly cash cost | B23: ='PM Tax reserve calculation'!B5+'PM Tax reserve calculation'!B6 -> 925 | C23: ='Model inputs'!B96+'Model inputs'!B87 -> 2133.2 | D23: ='Model inputs'!B97+'Model inputs'!B88 -> 7706
A24: PM Local net monthly burn | B24: ='PM Monthly economics'!B23-'PM Monthly economics'!B9 -> 925 | C24: ='PM Monthly economics'!C23-'PM Monthly economics'!C9 -> -1366.8 | D24: ='PM Monthly economics'!D23-'PM Monthly economics'!D9 -> -9794
A25: PM Local cash operating profit | B25: =-'PM Monthly economics'!B24 -> -925 | C25: =-'PM Monthly economics'!C24 -> 1366.8 | D25: =-'PM Monthly economics'!D24 -> 9794
A26: PM Local economic profit | B26: ='PM Monthly economics'!B25-('PM Hypothetical assumptions'!B41-'PM Hypothetical assumptions'!B35) -> -2825 | C26: ='PM Monthly economics'!C25-('Model inputs'!B9-'Model inputs'!B72) -> -533.2 | D26: ='PM Monthly economics'!D25-('Model inputs'!B10-'Model inputs'!B73) -> 7894
A27: PM Local runway months | B27: =IF(IF(IF(ISERROR('PM Monthly economics'!B24>0),'PM Monthly economics'!B24>0,IF('PM Monthly economics'!B24="","",'PM Monthly economics'!B24>0))="",FALSE(),IF(ISERROR('PM Monthly economics'!B24>0),'PM Monthly economics'!B24>0,IF('PM Monthly economics'!B24="","",'PM Monthly economics'!B24>0))),'PM Hypothetical assumptions'!B13/'PM Monthly economics'!B24,"") -> 5.4054054 | C27: =IF(IF(IF(ISERROR('PM Monthly economics'!C24>0),'PM Monthly economics'!C24>0,IF('PM Monthly economics'!C24="","",'PM Monthly economics'!C24>0))="",FALSE(),IF(ISERROR('PM Monthly economics'!C24>0),'PM Monthly economics'!C24>0,IF('PM Monthly economics'!C24="","",'PM Monthly economics'!C24>0))),'Model inputs'!B127/'PM Monthly economics'!C24,"") | D27: =IF(IF(IF(ISERROR('PM Monthly economics'!D24>0),'PM Monthly economics'!D24>0,IF('PM Monthly economics'!D24="","",'PM Monthly economics'!D24>0))="",FALSE(),IF(ISERROR('PM Monthly economics'!D24>0),'PM Monthly economics'!D24>0,IF('PM Monthly economics'!D24="","",'PM Monthly economics'!D24>0))),'Model inputs'!B129/'PM Monthly economics'!D24,"")
A28: PM Local runway status | B28: =IF(IF(IF(ISERROR('PM Monthly economics'!B24>0),'PM Monthly economics'!B24>0,IF('PM Monthly economics'!B24="","",'PM Monthly economics'!B24>0))="",FALSE(),IF(ISERROR('PM Monthly economics'!B24>0),'PM Monthly economics'!B24>0,IF('PM Monthly economics'!B24="","",'PM Monthly economics'!B24>0))),"Finite cash runway","No finite cash-runway limit") -> Finite cash runway | C28: =IF(IF(IF(ISERROR('PM Monthly economics'!C24>0),'PM Monthly economics'!C24>0,IF('PM Monthly economics'!C24="","",'PM Monthly economics'!C24>0))="",FALSE(),IF(ISERROR('PM Monthly economics'!C24>0),'PM Monthly economics'!C24>0,IF('PM Monthly economics'!C24="","",'PM Monthly economics'!C24>0))),"Finite cash runway","No finite cash-runway limit") -> No finite cash-runway limit | D28: =IF(IF(IF(ISERROR('PM Monthly economics'!D24>0),'PM Monthly economics'!D24>0,IF('PM Monthly economics'!D24="","",'PM Monthly economics'!D24>0))="",FALSE(),IF(ISERROR('PM Monthly economics'!D24>0),'PM Monthly economics'!D24>0,IF('PM Monthly economics'!D24="","",'PM Monthly economics'!D24>0))),"Finite cash runway","No finite cash-runway limit") -> No finite cash-runway limit
A29: PM Local post-validation runway | B29: =IF(IF(IF(ISERROR('PM Monthly economics'!B24>0),'PM Monthly economics'!B24>0,IF('PM Monthly economics'!B24="","",'PM Monthly economics'!B24>0))="",FALSE(),IF(ISERROR('PM Monthly economics'!B24>0),'PM Monthly economics'!B24>0,IF('PM Monthly economics'!B24="","",'PM Monthly economics'!B24>0))),('PM Hypothetical assumptions'!B13-'PM Hypothetical assumptions'!B14)/'PM Monthly economics'!B24,"") -> 3.7837838 | C29: =IF(IF(IF(ISERROR('PM Monthly economics'!C24>0),'PM Monthly economics'!C24>0,IF('PM Monthly economics'!C24="","",'PM Monthly economics'!C24>0))="",FALSE(),IF(ISERROR('PM Monthly economics'!C24>0),'PM Monthly economics'!C24>0,IF('PM Monthly economics'!C24="","",'PM Monthly economics'!C24>0))),('Model inputs'!B127-'Model inputs'!B145)/'PM Monthly economics'!C24,"") | D29: =IF(IF(IF(ISERROR('PM Monthly economics'!D24>0),'PM Monthly economics'!D24>0,IF('PM Monthly economics'!D24="","",'PM Monthly economics'!D24>0))="",FALSE(),IF(ISERROR('PM Monthly economics'!D24>0),'PM Monthly economics'!D24>0,IF('PM Monthly economics'!D24="","",'PM Monthly economics'!D24>0))),('Model inputs'!B129-'Model inputs'!B147)/'PM Monthly economics'!D24,"")
A30: PM Local break-even customers | B30: =IF(IF('PM Monthly economics'!B17-'PM Hypothetical assumptions'!B15*'PM Hypothetical assumptions'!B39>0="",FALSE(),'PM Monthly economics'!B17-'PM Hypothetical assumptions'!B15*'PM Hypothetical assumptions'!B39>0),CEILING(('PM Hypothetical assumptions'!B27+'PM Monthly economics'!B22)/('PM Monthly economics'!B17-'PM Hypothetical assumptions'!B15*'PM Hypothetical assumptions'!B39),1),"") -> 36 | C30: =IF(IF('PM Monthly economics'!C17-'Model inputs'!B114*'Model inputs'!B102>0="",FALSE(),'PM Monthly economics'!C17-'Model inputs'!B114*'Model inputs'!B102>0),CEILING(('Model inputs'!B69+'PM Monthly economics'!C22)/('PM Monthly economics'!C17-'Model inputs'!B114*'Model inputs'!B102),1),"") -> 36 | D30: =IF(IF('PM Monthly economics'!D17-'Model inputs'!B115*'Model inputs'!B103>0="",FALSE(),'PM Monthly economics'!D17-'Model inputs'!B115*'Model inputs'!B103>0),CEILING(('Model inputs'!B70+'PM Monthly economics'!D22)/('PM Monthly economics'!D17-'Model inputs'!B115*'Model inputs'!B103),1),"") -> 36
A31: PM Local CAC payback months | B31: =IF(IF(IF(ISERROR('PM Monthly economics'!B17>0),'PM Monthly economics'!B17>0,IF('PM Monthly economics'!B17="","",'PM Monthly economics'!B17>0))="",FALSE(),IF(ISERROR('PM Monthly economics'!B17>0),'PM Monthly economics'!B17>0,IF('PM Monthly economics'!B17="","",'PM Monthly economics'!B17>0))),'PM Hypothetical assumptions'!B39/'PM Monthly economics'!B17,"") -> 1.4526966 | C31: =IF(IF(IF(ISERROR('PM Monthly economics'!C17>0),'PM Monthly economics'!C17>0,IF('PM Monthly economics'!C17="","",'PM Monthly economics'!C17>0))="",FALSE(),IF(ISERROR('PM Monthly economics'!C17>0),'PM Monthly economics'!C17>0,IF('PM Monthly economics'!C17="","",'PM Monthly economics'!C17>0))),'Model inputs'!B102/'PM Monthly economics'!C17,"") -> 1.4526966 | D31: =IF(IF(IF(ISERROR('PM Monthly economics'!D17>0),'PM Monthly economics'!D17>0,IF('PM Monthly economics'!D17="","",'PM Monthly economics'!D17>0))="",FALSE(),IF(ISERROR('PM Monthly economics'!D17>0),'PM Monthly economics'!D17>0,IF('PM Monthly economics'!D17="","",'PM Monthly economics'!D17>0))),'Model inputs'!B103/'PM Monthly economics'!D17,"") -> 1.4526966
A32: PM Hosted support per customer | B32: =('PM Hypothetical assumptions'!B21*(1-'PM Hypothetical assumptions'!B6)+'PM Hypothetical assumptions'!B22*'PM Hypothetical assumptions'!B6)*'PM Hypothetical assumptions'!B18 -> 6 | C32: =('Model inputs'!B27*(1-'Model inputs'!B141)+'Model inputs'!B57*'Model inputs'!B141)*'Model inputs'!B132 -> 6 | D32: =('Model inputs'!B28*(1-'Model inputs'!B142)+'Model inputs'!B58*'Model inputs'!B142)*'Model inputs'!B133 -> 6
A33: PM Hosted compute storage per customer | B33: ='PM Hypothetical assumptions'!B25*(1-'PM Hypothetical assumptions'!B6)+'PM Hypothetical assumptions'!B26*'PM Hypothetical assumptions'!B6 -> 1.2 | C33: ='Model inputs'!B24*(1-'Model inputs'!B141)+'Model inputs'!B54*'Model inputs'!B141 -> 1.2 | D33: ='Model inputs'!B25*(1-'Model inputs'!B142)+'Model inputs'!B55*'Model inputs'!B142 -> 1.2
A34: PM Hosted variable cost per customer | B34: ='PM Monthly economics'!B12+'PM Monthly economics'!B13+'PM Monthly economics'!B32+'PM Monthly economics'!B33 -> 10.315 | C34: ='PM Monthly economics'!C12+'PM Monthly economics'!C13+'PM Monthly economics'!C32+'PM Monthly economics'!C33 -> 10.315 | D34: ='PM Monthly economics'!D12+'PM Monthly economics'!D13+'PM Monthly economics'!D32+'PM Monthly economics'!D33 -> 10.315
A35: PM Hosted contribution per customer | B35: ='PM Monthly economics'!B7-'PM Monthly economics'!B34 -> 24.685 | C35: ='PM Monthly economics'!C7-'PM Monthly economics'!C34 -> 24.685 | D35: ='PM Monthly economics'!D7-'PM Monthly economics'!D34 -> 24.685
A36: PM Hosted delivery COGS | B36: ='PM Hypothetical assumptions'!B5*'PM Monthly economics'!B34+'PM Hypothetical assumptions'!B28 -> 150 | C36: ='Model inputs'!B7*'PM Monthly economics'!C34+'Model inputs'!B15 -> 1181.5 | D36: ='Model inputs'!B8*'PM Monthly economics'!D34+'Model inputs'!B16 -> 5307.5
A37: PM Hosted gross profit | B37: ='PM Monthly economics'!B9-'PM Monthly economics'!B36 -> -150 | C37: ='PM Monthly economics'!C9-'PM Monthly economics'!C36 -> 2318.5 | D37: ='PM Monthly economics'!D9-'PM Monthly economics'!D36 -> 12192.5
A38: PM Hosted gross margin | B38: =IFERROR('PM Monthly economics'!B37/'PM Monthly economics'!B9,"") | C38: =IFERROR('PM Monthly economics'!C37/'PM Monthly economics'!C9,"") -> 0.66242857 | D38: =IFERROR('PM Monthly economics'!D37/'PM Monthly economics'!D9,"") -> 0.69671429
A39: PM Hosted replacement acquisition | B39: ='PM Monthly economics'!B11*'PM Hypothetical assumptions'!B40 -> 0 | C39: ='PM Monthly economics'!C11*'Model inputs'!B48 -> 195 | D39: ='PM Monthly economics'!D11*'Model inputs'!B49 -> 975
A40: PM Hosted fixed operating cash | B40: ='PM Hypothetical assumptions'!B30+'PM Hypothetical assumptions'!B32+'PM Hypothetical assumptions'!B34+'PM Hypothetical assumptions'!B36+'PM Hypothetical assumptions'!B38 -> 1550 | C40: ='Model inputs'!B51+'Model inputs'!B30+'Model inputs'!B12+'Model inputs'!B18+'Model inputs'!B21 -> 1550 | D40: ='Model inputs'!B52+'Model inputs'!B31+'Model inputs'!B13+'Model inputs'!B19+'Model inputs'!B22 -> 1550
A41: PM Hosted total monthly cash cost | B41: ='PM Tax reserve calculation'!B7+'PM Tax reserve calculation'!B8 -> 1700 | C41: ='Model inputs'!B42+'Model inputs'!B33 -> 3041.2 | D41: ='Model inputs'!B43+'Model inputs'!B34 -> 9766
...

Sheet PM Repair sensitivity
A1: PM Repair sensitivity
A2: Parity Medic · neatHack business plan · Main Scenario
A4: Variable / dimension | B4: PM Sensitivity repair cost | C4: PM Capped inference per customer | D4: PM Local Capped sensitivity burn | E4: PM Local Capped sensitivity runway | F4: PM Hosted Capped sensitivity burn | G4: PM Hosted Capped sensitivity runway | H4: PM Uncapped inference per customer | I4: PM Local Uncapped sensitivity burn | J4: PM Local Uncapped sensitivity runway | K4: PM Hosted Uncapped sensitivity burn | L4: PM Hosted Uncapped sensitivity runway
A5: Planning $0.05 | B5: =0.05 -> 0.05 | C5: ='PM Repair sensitivity'!B5*'PM Monthly economics'!B8 -> 1.8 | D5: =('PM Tax reserve calculation'!B5-'PM Monthly economics'!B9+'PM Hypothetical assumptions'!B5*('PM Repair sensitivity'!C5-'PM Monthly economics'!B12))+MAX(0,-('PM Tax reserve calculation'!B5-'PM Monthly economics'!B9+'PM Hypothetical assumptions'!B5*('PM Repair sensitivity'!C5-'PM Monthly economics'!B12)))*'PM Tax reserve assumption'!B5 -> 925 | E5: =IF(IF(IF(ISERROR('PM Repair sensitivity'!D5>0),'PM Repair sensitivity'!D5>0,IF('PM Repair sensitivity'!D5="","",'PM Repair sensitivity'!D5>0))="",FALSE(),IF(ISERROR('PM Repair sensitivity'!D5>0),'PM Repair sensitivity'!D5>0,IF('PM Repair sensitivity'!D5="","",'PM Repair sensitivity'!D5>0))),'PM Hypothetical assumptions'!B13/'PM Repair sensitivity'!D5,"") -> 5.4054054 | F5: =('PM Tax reserve calculation'!B7-'PM Monthly economics'!B9+'PM Hypothetical assumptions'!B5*('PM Repair sensitivity'!C5-'PM Monthly economics'!B12))+MAX(0,-('PM Tax reserve calculation'!B7-'PM Monthly economics'!B9+'PM Hypothetical assumptions'!B5*('PM Repair sensitivity'!C5-'PM Monthly economics'!B12)))*'PM Tax reserve assumption'!B5 -> 1700 | G5: =IF(IF(IF(ISERROR('PM Repair sensitivity'!F5>0),'PM Repair sensitivity'!F5>0,IF('PM Repair sensitivity'!F5="","",'PM Repair sensitivity'!F5>0))="",FALSE(),IF(ISERROR('PM Repair sensitivity'!F5>0),'PM Repair sensitivity'!F5>0,IF('PM Repair sensitivity'!F5="","",'PM Repair sensitivity'!F5>0))),'PM Hypothetical assumptions'!B13/'PM Repair sensitivity'!F5,"") -> 2.9411765 | H5: ='PM Repair sensitivity'!B5*'PM Hypothetical assumptions'!B11 -> 5 | I5: =('PM Tax reserve calculation'!B5-'PM Monthly economics'!B9+'PM Hypothetical assumptions'!B5*('PM Repair sensitivity'!H5-'PM Monthly economics'!B12))+MAX(0,-('PM Tax reserve calculation'!B5-'PM Monthly economics'!B9+'PM Hypothetical assumptions'!B5*('PM Repair sensitivity'!H5-'PM Monthly economics'!B12)))*'PM Tax reserve assumption'!B5 -> 925 | J5: =IF(IF(IF(ISERROR('PM Repair sensitivity'!I5>0),'PM Repair sensitivity'!I5>0,IF('PM Repair sensitivity'!I5="","",'PM Repair sensitivity'!I5>0))="",FALSE(),IF(ISERROR('PM Repair sensitivity'!I5>0),'PM Repair sensitivity'!I5>0,IF('PM Repair sensitivity'!I5="","",'PM Repair sensitivity'!I5>0))),'PM Hypothetical assumptions'!B13/'PM Repair sensitivity'!I5,"") -> 5.4054054 | K5: =('PM Tax reserve calculation'!B7-'PM Monthly economics'!B9+'PM Hypothetical assumptions'!B5*('PM Repair sensitivity'!H5-'PM Monthly economics'!B12))+MAX(0,-('PM Tax reserve calculation'!B7-'PM Monthly economics'!B9+'PM Hypothetical assumptions'!B5*('PM Repair sensitivity'!H5-'PM Monthly economics'!B12)))*'PM Tax reserve assumption'!B5 -> 1700 | L5: =IF(IF(IF(ISERROR('PM Repair sensitivity'!K5>0),'PM Repair sensitivity'!K5>0,IF('PM Repair sensitivity'!K5="","",'PM Repair sensitivity'!K5>0))="",FALSE(),IF(ISERROR('PM Repair sensitivity'!K5>0),'PM Repair sensitivity'!K5>0,IF('PM Repair sensitivity'!K5="","",'PM Repair sensitivity'!K5>0))),'PM Hypothetical assumptions'!B13/'PM Repair sensitivity'!K5,"") -> 2.9411765
A6: Severe $1.00 | B6: =1 -> 1 | C6: ='PM Repair sensitivity'!B6*'PM Monthly economics'!B8 -> 36 | D6: =('PM Tax reserve calculation'!B5-'PM Monthly economics'!B9+'PM Hypothetical assumptions'!B5*('PM Repair sensitivity'!C6-'PM Monthly economics'!B12))+MAX(0,-('PM Tax reserve calculation'!B5-'PM Monthly economics'!B9+'PM Hypothetical assumptions'!B5*('PM Repair sensitivity'!C6-'PM Monthly economics'!B12)))*'PM Tax reserve assumption'!B5 -> 925 | E6: =IF(IF(IF(ISERROR('PM Repair sensitivity'!D6>0),'PM Repair sensitivity'!D6>0,IF('PM Repair sensitivity'!D6="","",'PM Repair sensitivity'!D6>0))="",FALSE(),IF(ISERROR('PM Repair sensitivity'!D6>0),'PM Repair sensitivity'!D6>0,IF('PM Repair sensitivity'!D6="","",'PM Repair sensitivity'!D6>0))),'PM Hypothetical assumptions'!B13/'PM Repair sensitivity'!D6,"") -> 5.4054054 | F6: =('PM Tax reserve calculation'!B7-'PM Monthly economics'!B9+'PM Hypothetical assumptions'!B5*('PM Repair sensitivity'!C6-'PM Monthly economics'!B12))+MAX(0,-('PM Tax reserve calculation'!B7-'PM Monthly economics'!B9+'PM Hypothetical assumptions'!B5*('PM Repair sensitivity'!C6-'PM Monthly economics'!B12)))*'PM Tax reserve assumption'!B5 -> 1700 | G6: =IF(IF(IF(ISERROR('PM Repair sensitivity'!F6>0),'PM Repair sensitivity'!F6>0,IF('PM Repair sensitivity'!F6="","",'PM Repair sensitivity'!F6>0))="",FALSE(),IF(ISERROR('PM Repair sensitivity'!F6>0),'PM Repair sensitivity'!F6>0,IF('PM Repair sensitivity'!F6="","",'PM Repair sensitivity'!F6>0))),'PM Hypothetical assumptions'!B13/'PM Repair sensitivity'!F6,"") -> 2.9411765 | H6: ='PM Repair sensitivity'!B6*'PM Hypothetical assumptions'!B11 -> 100 | I6: =('PM Tax reserve calculation'!B5-'PM Monthly economics'!B9+'PM Hypothetical assumptions'!B5*('PM Repair sensitivity'!H6-'PM Monthly economics'!B12))+MAX(0,-('PM Tax reserve calculation'!B5-'PM Monthly economics'!B9+'PM Hypothetical assumptions'!B5*('PM Repair sensitivity'!H6-'PM Monthly economics'!B12)))*'PM Tax reserve assumption'!B5 -> 925 | J6: =IF(IF(IF(ISERROR('PM Repair sensitivity'!I6>0),'PM Repair sensitivity'!I6>0,IF('PM Repair sensitivity'!I6="","",'PM Repair sensitivity'!I6>0))="",FALSE(),IF(ISERROR('PM Repair sensitivity'!I6>0),'PM Repair sensitivity'!I6>0,IF('PM Repair sensitivity'!I6="","",'PM Repair sensitivity'!I6>0))),'PM Hypothetical assumptions'!B13/'PM Repair sensitivity'!I6,"") -> 5.4054054 | K6: =('PM Tax reserve calculation'!B7-'PM Monthly economics'!B9+'PM Hypothetical assumptions'!B5*('PM Repair sensitivity'!H6-'PM Monthly economics'!B12))+MAX(0,-('PM Tax reserve calculation'!B7-'PM Monthly economics'!B9+'PM Hypothetical assumptions'!B5*('PM Repair sensitivity'!H6-'PM Monthly economics'!B12)))*'PM Tax reserve assumption'!B5 -> 1700 | L6: =IF(IF(IF(ISERROR('PM Repair sensitivity'!K6>0),'PM Repair sensitivity'!K6>0,IF('PM Repair sensitivity'!K6="","",'PM Repair sensitivity'!K6>0))="",FALSE(),IF(ISERROR('PM Repair sensitivity'!K6>0),'PM Repair sensitivity'!K6>0,IF('PM Repair sensitivity'!K6="","",'PM Repair sensitivity'!K6>0))),'PM Hypothetical assumptions'!B13/'PM Repair sensitivity'!K6,"") -> 2.9411765
A7: Stress $0.25 | B7: =0.25 -> 0.25 | C7: ='PM Repair sensitivity'!B7*'PM Monthly economics'!B8 -> 9 | D7: =('PM Tax reserve calculation'!B5-'PM Monthly economics'!B9+'PM Hypothetical assumptions'!B5*('PM Repair sensitivity'!C7-'PM Monthly economics'!B12))+MAX(0,-('PM Tax reserve calculation'!B5-'PM Monthly economics'!B9+'PM Hypothetical assumptions'!B5*('PM Repair sensitivity'!C7-'PM Monthly economics'!B12)))*'PM Tax reserve assumption'!B5 -> 925 | E7: =IF(IF(IF(ISERROR('PM Repair sensitivity'!D7>0),'PM Repair sensitivity'!D7>0,IF('PM Repair sensitivity'!D7="","",'PM Repair sensitivity'!D7>0))="",FALSE(),IF(ISERROR('PM Repair sensitivity'!D7>0),'PM Repair sensitivity'!D7>0,IF('PM Repair sensitivity'!D7="","",'PM Repair sensitivity'!D7>0))),'PM Hypothetical assumptions'!B13/'PM Repair sensitivity'!D7,"") -> 5.4054054 | F7: =('PM Tax reserve calculation'!B7-'PM Monthly economics'!B9+'PM Hypothetical assumptions'!B5*('PM Repair sensitivity'!C7-'PM Monthly economics'!B12))+MAX(0,-('PM Tax reserve calculation'!B7-'PM Monthly economics'!B9+'PM Hypothetical assumptions'!B5*('PM Repair sensitivity'!C7-'PM Monthly economics'!B12)))*'PM Tax reserve assumption'!B5 -> 1700 | G7: =IF(IF(IF(ISERROR('PM Repair sensitivity'!F7>0),'PM Repair sensitivity'!F7>0,IF('PM Repair sensitivity'!F7="","",'PM Repair sensitivity'!F7>0))="",FALSE(),IF(ISERROR('PM Repair sensitivity'!F7>0),'PM Repair sensitivity'!F7>0,IF('PM Repair sensitivity'!F7="","",'PM Repair sensitivity'!F7>0))),'PM Hypothetical assumptions'!B13/'PM Repair sensitivity'!F7,"") -> 2.9411765 | H7: ='PM Repair sensitivity'!B7*'PM Hypothetical assumptions'!B11 -> 25 | I7: =('PM Tax reserve calculation'!B5-'PM Monthly economics'!B9+'PM Hypothetical assumptions'!B5*('PM Repair sensitivity'!H7-'PM Monthly economics'!B12))+MAX(0,-('PM Tax reserve calculation'!B5-'PM Monthly economics'!B9+'PM Hypothetical assumptions'!B5*('PM Repair sensitivity'!H7-'PM Monthly economics'!B12)))*'PM Tax reserve assumption'!B5 -> 925 | J7: =IF(IF(IF(ISERROR('PM Repair sensitivity'!I7>0),'PM Repair sensitivity'!I7>0,IF('PM Repair sensitivity'!I7="","",'PM Repair sensitivity'!I7>0))="",FALSE(),IF(ISERROR('PM Repair sensitivity'!I7>0),'PM Repair sensitivity'!I7>0,IF('PM Repair sensitivity'!I7="","",'PM Repair sensitivity'!I7>0))),'PM Hypothetical assumptions'!B13/'PM Repair sensitivity'!I7,"") -> 5.4054054 | K7: =('PM Tax reserve calculation'!B7-'PM Monthly economics'!B9+'PM Hypothetical assumptions'!B5*('PM Repair sensitivity'!H7-'PM Monthly economics'!B12))+MAX(0,-('PM Tax reserve calculation'!B7-'PM Monthly economics'!B9+'PM Hypothetical assumptions'!B5*('PM Repair sensitivity'!H7-'PM Monthly economics'!B12)))*'PM Tax reserve assumption'!B5 -> 1700 | L7: =IF(IF(IF(ISERROR('PM Repair sensitivity'!K7>0),'PM Repair sensitivity'!K7>0,IF('PM Repair sensitivity'!K7="","",'PM Repair sensitivity'!K7>0))="",FALSE(),IF(ISERROR('PM Repair sensitivity'!K7>0),'PM Repair sensitivity'!K7>0,IF('PM Repair sensitivity'!K7="","",'PM Repair sensitivity'!K7>0))),'PM Hypothetical assumptions'!B13/'PM Repair sensitivity'!K7,"") -> 2.9411765

Sheet PM Pricing sensitivity
A1: PM Pricing sensitivity
A2: Parity Medic · neatHack business plan · Main Scenario
A4: Variable / dimension | B4: PM Price factor | C4: PM Sensitivity ARPU | D4: PM Local pricing burn | E4: PM Local pricing runway | F4: PM Hosted pricing burn | G4: PM Hosted pricing runway
A5: 25% higher | B5: =1.25 -> 1.25 | C5: ='PM Monthly economics'!B7*'PM Pricing sensitivity'!B5 -> 43.75 | D5: =('PM Tax reserve calculation'!B5-'PM Monthly economics'!B9-'PM Hypothetical assumptions'!B5*('PM Pricing sensitivity'!C5-'PM Monthly economics'!B7)*(1-'PM Hypothetical assumptions'!B16))+MAX(0,-('PM Tax reserve calculation'!B5-'PM Monthly economics'!B9-'PM Hypothetical assumptions'!B5*('PM Pricing sensitivity'!C5-'PM Monthly economics'!B7)*(1-'PM Hypothetical assumptions'!B16)))*'PM Tax reserve assumption'!B5 -> 925 | E5: =IF(IF(IF(ISERROR('PM Pricing sensitivity'!D5>0),'PM Pricing sensitivity'!D5>0,IF('PM Pricing sensitivity'!D5="","",'PM Pricing sensitivity'!D5>0))="",FALSE(),IF(ISERROR('PM Pricing sensitivity'!D5>0),'PM Pricing sensitivity'!D5>0,IF('PM Pricing sensitivity'!D5="","",'PM Pricing sensitivity'!D5>0))),'PM Hypothetical assumptions'!B13/'PM Pricing sensitivity'!D5,"") -> 5.4054054 | F5: =('PM Tax reserve calculation'!B7-'PM Monthly economics'!B9-'PM Hypothetical assumptions'!B5*('PM Pricing sensitivity'!C5-'PM Monthly economics'!B7)*(1-'PM Hypothetical assumptions'!B16))+MAX(0,-('PM Tax reserve calculation'!B7-'PM Monthly economics'!B9-'PM Hypothetical assumptions'!B5*('PM Pricing sensitivity'!C5-'PM Monthly economics'!B7)*(1-'PM Hypothetical assumptions'!B16)))*'PM Tax reserve assumption'!B5 -> 1700 | G5: =IF(IF(IF(ISERROR('PM Pricing sensitivity'!F5>0),'PM Pricing sensitivity'!F5>0,IF('PM Pricing sensitivity'!F5="","",'PM Pricing sensitivity'!F5>0))="",FALSE(),IF(ISERROR('PM Pricing sensitivity'!F5>0),'PM Pricing sensitivity'!F5>0,IF('PM Pricing sensitivity'!F5="","",'PM Pricing sensitivity'!F5>0))),'PM Hypothetical assumptions'!B13/'PM Pricing sensitivity'!F5,"") -> 2.9411765
A6: 25% lower | B6: =0.75 -> 0.75 | C6: ='PM Monthly economics'!B7*'PM Pricing sensitivity'!B6 -> 26.25 | D6: =('PM Tax reserve calculation'!B5-'PM Monthly economics'!B9-'PM Hypothetical assumptions'!B5*('PM Pricing sensitivity'!C6-'PM Monthly economics'!B7)*(1-'PM Hypothetical assumptions'!B16))+MAX(0,-('PM Tax reserve calculation'!B5-'PM Monthly economics'!B9-'PM Hypothetical assumptions'!B5*('PM Pricing sensitivity'!C6-'PM Monthly economics'!B7)*(1-'PM Hypothetical assumptions'!B16)))*'PM Tax reserve assumption'!B5 -> 925 | E6: =IF(IF(IF(ISERROR('PM Pricing sensitivity'!D6>0),'PM Pricing sensitivity'!D6>0,IF('PM Pricing sensitivity'!D6="","",'PM Pricing sensitivity'!D6>0))="",FALSE(),IF(ISERROR('PM Pricing sensitivity'!D6>0),'PM Pricing sensitivity'!D6>0,IF('PM Pricing sensitivity'!D6="","",'PM Pricing sensitivity'!D6>0))),'PM Hypothetical assumptions'!B13/'PM Pricing sensitivity'!D6,"") -> 5.4054054 | F6: =('PM Tax reserve calculation'!B7-'PM Monthly economics'!B9-'PM Hypothetical assumptions'!B5*('PM Pricing sensitivity'!C6-'PM Monthly economics'!B7)*(1-'PM Hypothetical assumptions'!B16))+MAX(0,-('PM Tax reserve calculation'!B7-'PM Monthly economics'!B9-'PM Hypothetical assumptions'!B5*('PM Pricing sensitivity'!C6-'PM Monthly economics'!B7)*(1-'PM Hypothetical assumptions'!B16)))*'PM Tax reserve assumption'!B5 -> 1700 | G6: =IF(IF(IF(ISERROR('PM Pricing sensitivity'!F6>0),'PM Pricing sensitivity'!F6>0,IF('PM Pricing sensitivity'!F6="","",'PM Pricing sensitivity'!F6>0))="",FALSE(),IF(ISERROR('PM Pricing sensitivity'!F6>0),'PM Pricing sensitivity'!F6>0,IF('PM Pricing sensitivity'!F6="","",'PM Pricing sensitivity'!F6>0))),'PM Hypothetical assumptions'!B13/'PM Pricing sensitivity'!F6,"") -> 2.9411765
A7: Proposed price | B7: =1 -> 1 | C7: ='PM Monthly economics'!B7*'PM Pricing sensitivity'!B7 -> 35 | D7: =('PM Tax reserve calculation'!B5-'PM Monthly economics'!B9-'PM Hypothetical assumptions'!B5*('PM Pricing sensitivity'!C7-'PM Monthly economics'!B7)*(1-'PM Hypothetical assumptions'!B16))+MAX(0,-('PM Tax reserve calculation'!B5-'PM Monthly economics'!B9-'PM Hypothetical assumptions'!B5*('PM Pricing sensitivity'!C7-'PM Monthly economics'!B7)*(1-'PM Hypothetical assumptions'!B16)))*'PM Tax reserve assumption'!B5 -> 925 | E7: =IF(IF(IF(ISERROR('PM Pricing sensitivity'!D7>0),'PM Pricing sensitivity'!D7>0,IF('PM Pricing sensitivity'!D7="","",'PM Pricing sensitivity'!D7>0))="",FALSE(),IF(ISERROR('PM Pricing sensitivity'!D7>0),'PM Pricing sensitivity'!D7>0,IF('PM Pricing sensitivity'!D7="","",'PM Pricing sensitivity'!D7>0))),'PM Hypothetical assumptions'!B13/'PM Pricing sensitivity'!D7,"") -> 5.4054054 | F7: =('PM Tax reserve calculation'!B7-'PM Monthly economics'!B9-'PM Hypothetical assumptions'!B5*('PM Pricing sensitivity'!C7-'PM Monthly economics'!B7)*(1-'PM Hypothetical assumptions'!B16))+MAX(0,-('PM Tax reserve calculation'!B7-'PM Monthly economics'!B9-'PM Hypothetical assumptions'!B5*('PM Pricing sensitivity'!C7-'PM Monthly economics'!B7)*(1-'PM Hypothetical assumptions'!B16)))*'PM Tax reserve assumption'!B5 -> 1700 | G7: =IF(IF(IF(ISERROR('PM Pricing sensitivity'!F7>0),'PM Pricing sensitivity'!F7>0,IF('PM Pricing sensitivity'!F7="","",'PM Pricing sensitivity'!F7>0))="",FALSE(),IF(ISERROR('PM Pricing sensitivity'!F7>0),'PM Pricing sensitivity'!F7>0,IF('PM Pricing sensitivity'!F7="","",'PM Pricing sensitivity'!F7>0))),'PM Hypothetical assumptions'!B13/'PM Pricing sensitivity'!F7,"") -> 2.9411765

Sheet PM Validation budget
A1: PM Validation budget
A2: Parity Medic · neatHack business plan · Main Scenario
A4: Variable / dimension | B4: PM Validation workstream cost
A5: CI exports and drift evidence | B5: =100 -> 100
A6: Limited pilot support | B6: =200 -> 200
A7: Preregistered fresh evaluation | B7: =300 -> 300
A8: Second contract and provider | B8: =350 -> 350
A9: Security and recovery review | B9: =400 -> 400
A10: Wrapper interviews | B10: =150 -> 150

Sheet PM Tier economics
A1: PM Tier economics
A2: Parity Medic · neatHack business plan · Main Scenario
A4: Variable / dimension | B4: PM Offer price | C4: PM Offer included repairs | D4: PM Offer inference baseline | E4: PM Offer inference expensive | F4: PM Offer uncapped inference baseline | G4: PM Offer uncapped inference severe | H4: PM Local offer support | I4: PM Local offer compute | J4: PM Local offer baseline contribution | K4: PM Local offer severe contribution | L4: PM Hosted offer support | M4: PM Hosted offer compute | N4: PM Hosted offer baseline contribution | O4: PM Hosted offer severe contribution
A5: Individual | B5: =IF(EXACT("Individual","Individual"),IF('PM Hypothetical assumptions'!B7="","",'PM Hypothetical assumptions'!B7),IF('PM Hypothetical assumptions'!B8="","",'PM Hypothetical assumptions'!B8)) -> 19 | C5: =IF(EXACT("Individual","Individual"),IF('PM Hypothetical assumptions'!B9="","",'PM Hypothetical assumptions'!B9),IF('PM Hypothetical assumptions'!B10="","",'PM Hypothetical assumptions'!B10)) -> 20 | D5: ='PM Tier economics'!C5*'PM Hypothetical assumptions'!B12 -> 1 | E5: ='PM Tier economics'!C5*'PM Repair sensitivity'!B6 -> 20 | F5: ='PM Hypothetical assumptions'!B11*'PM Hypothetical assumptions'!B12 -> 5 | G5: ='PM Hypothetical assumptions'!B11*'PM Repair sensitivity'!B6 -> 100 | H5: =IF(IF(EXACT("Individual","Individual"),IF('PM Hypothetical assumptions'!B19="","",'PM Hypothetical assumptions'!B19),IF('PM Hypothetical assumptions'!B20="","",'PM Hypothetical assumptions'!B20))="",0,IF(EXACT("Individual","Individual"),IF('PM Hypothetical assumptions'!B19="","",'PM Hypothetical assumptions'!B19),IF('PM Hypothetical assumptions'!B20="","",'PM Hypothetical assumptions'!B20)))*'PM Hypothetical assumptions'!B18 -> 2.5 | I5: =IF(EXACT("Individual","Individual"),IF('PM Hypothetical assumptions'!B23="","",'PM Hypothetical assumptions'!B23),IF('PM Hypothetical assumptions'!B24="","",'PM Hypothetical assumptions'!B24)) -> 0.25 | J5: ='PM Tier economics'!B5*(1-'PM Hypothetical assumptions'!B16)-'PM Hypothetical assumptions'!B17-'PM Tier economics'!D5-'PM Tier economics'!H5-'PM Tier economics'!I5 -> 14.399 | K5: ='PM Tier economics'!B5*(1-'PM Hypothetical assumptions'!B16)-'PM Hypothetical assumptions'!B17-'PM Tier economics'!E5-'PM Tier economics'!H5-'PM Tier economics'!I5 -> -4.601 | L5: =IF(IF(EXACT("Individual","Individual"),IF('PM Hypothetical assumptions'!B21="","",'PM Hypothetical assumptions'!B21),IF('PM Hypothetical assumptions'!B22="","",'PM Hypothetical assumptions'!B22))="",0,IF(EXACT("Individual","Individual"),IF('PM Hypothetical assumptions'!B21="","",'PM Hypothetical assumptions'!B21),IF('PM Hypothetical assumptions'!B22="","",'PM Hypothetical assumptions'!B22)))*'PM Hypothetical assumptions'!B18 -> 3.75 | M5: =IF(EXACT("Individual","Individual"),IF('PM Hypothetical assumptions'!B25="","",'PM Hypothetical assumptions'!B25),IF('PM Hypothetical assumptions'!B26="","",'PM Hypothetical assumptions'!B26)) -> 0.75 | N5: ='PM Tier economics'!B5*(1-'PM Hypothetical assumptions'!B16)-'PM Hypothetical assumptions'!B17-'PM Tier economics'!D5-'PM Tier economics'!L5-'PM Tier economics'!M5 -> 12.649 | O5: ='PM Tier economics'!B5*(1-'PM Hypothetical assumptions'!B16)-'PM Hypothetical assumptions'!B17-'PM Tier economics'!E5-'PM Tier economics'!L5-'PM Tier economics'!M5 -> -6.351
A6: Team | B6: =IF(EXACT("Team","Individual"),IF('PM Hypothetical assumptions'!B7="","",'PM Hypothetical assumptions'!B7),IF('PM Hypothetical assumptions'!B8="","",'PM Hypothetical assumptions'!B8)) -> 99 | C6: =IF(EXACT("Team","Individual"),IF('PM Hypothetical assumptions'!B9="","",'PM Hypothetical assumptions'!B9),IF('PM Hypothetical assumptions'!B10="","",'PM Hypothetical assumptions'!B10)) -> 100 | D6: ='PM Tier economics'!C6*'PM Hypothetical assumptions'!B12 -> 5 | E6: ='PM Tier economics'!C6*'PM Repair sensitivity'!B6 -> 100 | F6: ='PM Hypothetical assumptions'!B11*'PM Hypothetical assumptions'!B12 -> 5 | G6: ='PM Hypothetical assumptions'!B11*'PM Repair sensitivity'!B6 -> 100 | H6: =IF(IF(EXACT("Team","Individual"),IF('PM Hypothetical assumptions'!B19="","",'PM Hypothetical assumptions'!B19),IF('PM Hypothetical assumptions'!B20="","",'PM Hypothetical assumptions'!B20))="",0,IF(EXACT("Team","Individual"),IF('PM Hypothetical assumptions'!B19="","",'PM Hypothetical assumptions'!B19),IF('PM Hypothetical assumptions'!B20="","",'PM Hypothetical assumptions'!B20)))*'PM Hypothetical assumptions'!B18 -> 10 | I6: =IF(EXACT("Team","Individual"),IF('PM Hypothetical assumptions'!B23="","",'PM Hypothetical assumptions'!B23),IF('PM Hypothetical assumptions'!B24="","",'PM Hypothetical assumptions'!B24)) -> 0.75 | J6: ='PM Tier economics'!B6*(1-'PM Hypothetical assumptions'!B16)-'PM Hypothetical assumptions'!B17-'PM Tier economics'!D6-'PM Tier economics'!H6-'PM Tier economics'!I6 -> 80.079 | K6: ='PM Tier economics'!B6*(1-'PM Hypothetical assumptions'!B16)-'PM Hypothetical assumptions'!B17-'PM Tier economics'!E6-'PM Tier economics'!H6-'PM Tier economics'!I6 -> -14.921 | L6: =IF(IF(EXACT("Team","Individual"),IF('PM Hypothetical assumptions'!B21="","",'PM Hypothetical assumptions'!B21),IF('PM Hypothetical assumptions'!B22="","",'PM Hypothetical assumptions'!B22))="",0,IF(EXACT("Team","Individual"),IF('PM Hypothetical assumptions'!B21="","",'PM Hypothetical assumptions'!B21),IF('PM Hypothetical assumptions'!B22="","",'PM Hypothetical assumptions'!B22)))*'PM Hypothetical assumptions'!B18 -> 15 | M6: =IF(EXACT("Team","Individual"),IF('PM Hypothetical assumptions'!B25="","",'PM Hypothetical assumptions'!B25),IF('PM Hypothetical assumptions'!B26="","",'PM Hypothetical assumptions'!B26)) -> 3 | N6: ='PM Tier economics'!B6*(1-'PM Hypothetical assumptions'!B16)-'PM Hypothetical assumptions'!B17-'PM Tier economics'!D6-'PM Tier economics'!L6-'PM Tier economics'!M6 -> 72.829 | O6: ='PM Tier economics'!B6*(1-'PM Hypothetical assumptions'!B16)-'PM Hypothetical assumptions'!B17-'PM Tier economics'!E6-'PM Tier economics'!L6-'PM Tier economics'!M6 -> -22.171

Sheet PM 12-month cash projection
A1: PM 12-month cash projection
A2: Parity Medic · neatHack business plan · Main Scenario
A4: Variable / dimension | B4: 2026-10 | C4: 2026-10 > Parity Medic · 100 customers | D4: 2026-10 > Parity Medic · 500 customers | E4: 2026-11 | F4: 2026-11 > Parity Medic · 100 customers | G4: 2026-11 > Parity Medic · 500 customers | H4: 2026-12 | I4: 2026-12 > Parity Medic · 100 customers | J4: 2026-12 > Parity Medic · 500 customers | K4: 2027-01 | L4: 2027-01 > Parity Medic · 100 customers | M4: 2027-01 > Parity Medic · 500 customers | N4: 2027-02 | O4: 2027-02 > Parity Medic · 100 customers | P4: 2027-02 > Parity Medic · 500 customers | Q4: 2027-03 | R4: 2027-03 > Parity Medic · 100 customers | S4: 2027-03 > Parity Medic · 500 customers | T4: 2027-04 | U4: 2027-04 > Parity Medic · 100 customers | V4: 2027-04 > Parity Medic · 500 customers | W4: 2027-05 | X4: 2027-05 > Parity Medic · 100 customers | Y4: 2027-05 > Parity Medic · 500 customers | Z4: 2027-06 | AA4: 2027-06 > Parity Medic · 100 customers | AB4: 2027-06 > Parity Medic · 500 customers | AC4: 2027-07 | AD4: 2027-07 > Parity Medic · 100 customers | AE4: 2027-07 > Parity Medic · 500 customers | AF4: 2027-08 | AG4: 2027-08 > Parity Medic · 100 customers | AH4: 2027-08 > Parity Medic · 500 customers | AI4: 2027-09 | AJ4: 2027-09 > Parity Medic · 100 customers | AK4: 2027-09 > Parity Medic · 500 customers
A5: PM Local projected cash | B5: ='PM Hypothetical assumptions'!B13-'PM Hypothetical assumptions'!B14-'PM Monthly economics'!B24 -> 2575 | C5: ='Model inputs'!B127-'Model inputs'!B145-'PM Monthly economics'!C24 -> 4866.8 | D5: ='Model inputs'!B129-'Model inputs'!B147-'PM Monthly economics'!D24 -> 13294 | E5: ='PM 12-month cash projection'!B5-'PM Monthly economics'!B24 -> 1650 | F5: ='PM 12-month cash projection'!C5-'PM Monthly economics'!C24 -> 6233.6 | G5: ='PM 12-month cash projection'!D5-'PM Monthly economics'!D24 -> 23088 | H5: ='PM 12-month cash projection'!E5-'PM Monthly economics'!B24 -> 725 | I5: ='PM 12-month cash projection'!F5-'PM Monthly economics'!C24 -> 7600.4 | J5: ='PM 12-month cash projection'!G5-'PM Monthly economics'!D24 -> 32882 | K5: ='PM 12-month cash projection'!H5-'PM Monthly economics'!B24 -> -200 | L5: ='PM 12-month cash projection'!I5-'PM Monthly economics'!C24 -> 8967.2 | M5: ='PM 12-month cash projection'!J5-'PM Monthly economics'!D24 -> 42676 | N5: ='PM 12-month cash projection'!K5-'PM Monthly economics'!B24 -> -1125 | O5: ='PM 12-month cash projection'!L5-'PM Monthly economics'!C24 -> 10334 | P5: ='PM 12-month cash projection'!M5-'PM Monthly economics'!D24 -> 52470 | Q5: ='PM 12-month cash projection'!N5-'PM Monthly economics'!B24 -> -2050 | R5: ='PM 12-month cash projection'!O5-'PM Monthly economics'!C24 -> 11700.8 | S5: ='PM 12-month cash projection'!P5-'PM Monthly economics'!D24 -> 62264 | T5: ='PM 12-month cash projection'!Q5-'PM Monthly economics'!B24 -> -2975 | U5: ='PM 12-month cash projection'!R5-'PM Monthly economics'!C24 -> 13067.6 | V5: ='PM 12-month cash projection'!S5-'PM Monthly economics'!D24 -> 72058 | W5: ='PM 12-month cash projection'!T5-'PM Monthly economics'!B24 -> -3900 | X5: ='PM 12-month cash projection'!U5-'PM Monthly economics'!C24 -> 14434.4 | Y5: ='PM 12-month cash projection'!V5-'PM Monthly economics'!D24 -> 81852 | Z5: ='PM 12-month cash projection'!W5-'PM Monthly economics'!B24 -> -4825 | AA5: ='PM 12-month cash projection'!X5-'PM Monthly economics'!C24 -> 15801.2 | AB5: ='PM 12-month cash projection'!Y5-'PM Monthly economics'!D24 -> 91646 | AC5: ='PM 12-month cash projection'!Z5-'PM Monthly economics'!B24 -> -5750 | AD5: ='PM 12-month cash projection'!AA5-'PM Monthly economics'!C24 -> 17168 | AE5: ='PM 12-month cash projection'!AB5-'PM Monthly economics'!D24 -> 101440 | AF5: ='PM 12-month cash projection'!AC5-'PM Monthly economics'!B24 -> -6675 | AG5: ='PM 12-month cash projection'!AD5-'PM Monthly economics'!C24 -> 18534.8 | AH5: ='PM 12-month cash projection'!AE5-'PM Monthly economics'!D24 -> 111234 | AI5: ='PM 12-month cash projection'!AF5-'PM Monthly economics'!B24 -> -7600 | AJ5: ='PM 12-month cash projection'!AG5-'PM Monthly economics'!C24 -> 19901.6 | AK5: ='PM 12-month cash projection'!AH5-'PM Monthly economics'!D24 -> 121028
A6: PM Hosted projected cash | B6: ='PM Hypothetical assumptions'!B13-'PM Hypothetical assumptions'!B14-'PM Monthly economics'!B42 -> 1800 | C6: ='Model inputs'!B127-'Model inputs'!B145-'PM Monthly economics'!C42 -> 3958.8 | D6: ='Model inputs'!B129-'Model inputs'!B147-'PM Monthly economics'!D42 -> 11234 | E6: ='PM 12-month cash projection'!B6-'PM Monthly economics'!B42 -> 100 | F6: ='PM 12-month cash projection'!C6-'PM Monthly economics'!C42 -> 4417.6 | G6: ='PM 12-month cash projection'!D6-'PM Monthly economics'!D42 -> 18968 | H6: ='PM 12-month cash projection'!E6-'PM Monthly economics'!B42 -> -1600 | I6: ='PM 12-month cash projection'!F6-'PM Monthly economics'!C42 -> 4876.4 | J6: ='PM 12-month cash projection'!G6-'PM Monthly economics'!D42 -> 26702 | K6: ='PM 12-month cash projection'!H6-'PM Monthly economics'!B42 -> -3300 | L6: ='PM 12-month cash projection'!I6-'PM Monthly economics'!C42 -> 5335.2 | M6: ='PM 12-month cash projection'!J6-'PM Monthly economics'!D42 -> 34436 | N6: ='PM 12-month cash projection'!K6-'PM Monthly economics'!B42 -> -5000 | O6: ='PM 12-month cash projection'!L6-'PM Monthly economics'!C42 -> 5794 | P6: ='PM 12-month cash projection'!M6-'PM Monthly economics'!D42 -> 42170 | Q6: ='PM 12-month cash projection'!N6-'PM Monthly economics'!B42 -> -6700 | R6: ='PM 12-month cash projection'!O6-'PM Monthly economics'!C42 -> 6252.8 | S6: ='PM 12-month cash projection'!P6-'PM Monthly economics'!D42 -> 49904 | T6: ='PM 12-month cash projection'!Q6-'PM Monthly economics'!B42 -> -8400 | U6: ='PM 12-month cash projection'!R6-'PM Monthly economics'!C42 -> 6711.6 | V6: ='PM 12-month cash projection'!S6-'PM Monthly economics'!D42 -> 57638 | W6: ='PM 12-month cash projection'!T6-'PM Monthly economics'!B42 -> -10100 | X6: ='PM 12-month cash projection'!U6-'PM Monthly economics'!C42 -> 7170.4 | Y6: ='PM 12-month cash projection'!V6-'PM Monthly economics'!D42 -> 65372 | Z6: ='PM 12-month cash projection'!W6-'PM Monthly economics'!B42 -> -11800 | AA6: ='PM 12-month cash projection'!X6-'PM Monthly economics'!C42 -> 7629.2 | AB6: ='PM 12-month cash projection'!Y6-'PM Monthly economics'!D42 -> 73106 | AC6: ='PM 12-month cash projection'!Z6-'PM Monthly economics'!B42 -> -13500 | AD6: ='PM 12-month cash projection'!AA6-'PM Monthly economics'!C42 -> 8088 | AE6: ='PM 12-month cash projection'!AB6-'PM Monthly economics'!D42 -> 80840 | AF6: ='PM 12-month cash projection'!AC6-'PM Monthly economics'!B42 -> -15200 | AG6: ='PM 12-month cash projection'!AD6-'PM Monthly economics'!C42 -> 8546.8 | AH6: ='PM 12-month cash projection'!AE6-'PM Monthly economics'!D42 -> 88574 | AI6: ='PM 12-month cash projection'!AF6-'PM Monthly economics'!B42 -> -16900 | AJ6: ='PM 12-month cash projection'!AG6-'PM Monthly economics'!C42 -> 9005.6 | AK6: ='PM 12-month cash projection'!AH6-'PM Monthly economics'!D42 -> 96308

Sheet PM Tax reserve assumption
A1: PM Tax reserve assumption
A2: Parity Medic · neatHack business plan · Main Scenario
A4: Variable / dimension | B4: Value
A5: PM Hypothetical income tax reserve rate | B5: =0.2 -> 0.2

Sheet PM Tax reserve calculation
A1: PM Tax reserve calculation
A2: Parity Medic · neatHack business plan · Main Scenario
A4: Variable / dimension | B4: Value
A5: PM Local pre-tax monthly cash cost | B5: ='PM Monthly economics'!B18+'PM Monthly economics'!B21+'PM Monthly economics'!B22 -> 925
A6: PM Local monthly tax reserve | B6: =MAX(0,'PM Monthly economics'!B9-'PM Tax reserve calculation'!B5)*'PM Tax reserve assumption'!B5 -> 0
A7: PM Hosted pre-tax monthly cash cost | B7: ='PM Monthly economics'!B36+'PM Monthly economics'!B39+'PM Monthly economics'!B40 -> 1700
A8: PM Hosted monthly tax reserve | B8: =MAX(0,'PM Monthly economics'!B9-'PM Tax reserve calculation'!B7)*'PM Tax reserve assumption'!B5 -> 0

Sheet Model inputs
A1: Model inputs
A2: Integration values are aggregated snapshots; raw source records are not included.
A4: Variables
A5: Variable / segment | B5: Value | C5: Value | D5: 2026-09 | E5: 2026-10 | F5: 2026-11 | G5: 2026-12 | H5: 2027-01 | I5: 2027-02 | J5: 2027-03 | K5: 2027-04 | L5: 2027-05 | M5: 2027-06 | N5: 2027-07 | O5: 2027-08 | P5: 2027-09 | Q5: 2026-01 | R5: 2026-02 | S5: 2026-03 | T5: 2026-04 | U5: 2026-05 | V5: 2026-06 | W5: 2026-07 | X5: 2026-08
A6: PM Customers · PM Monthly economics · Main Scenario | B6: ='PM Hypothetical assumptions'!B5 -> 0
A7: PM Customers · PM Monthly economics · Parity Medic · 100 customers | B7: =100 -> 100
A8: PM Customers · PM Monthly economics · Parity Medic · 500 customers | B8: =500 -> 500
A9: PM Founder fair monthly compensation · Parity Medic · 100 customers | B9: ='PM Hypothetical assumptions'!B41 -> 2500
A10: PM Founder fair monthly compensation · Parity Medic · 500 customers | B10: ='PM Hypothetical assumptions'!B41 -> 2500
A11: PM Hosted administration · PM Monthly economics · Main Scenario | B11: ='PM Hypothetical assumptions'!B34 -> 40
A12: PM Hosted administration · Parity Medic · 100 customers | B12: ='PM Hypothetical assumptions'!B34 -> 40
A13: PM Hosted administration · Parity Medic · 500 customers | B13: ='PM Hypothetical assumptions'!B34 -> 40
A14: PM Hosted fixed delivery · PM Monthly economics · Main Scenario | B14: ='PM Hypothetical assumptions'!B28 -> 150
A15: PM Hosted fixed delivery · Parity Medic · 100 customers | B15: ='PM Hypothetical assumptions'!B28 -> 150
A16: PM Hosted fixed delivery · Parity Medic · 500 customers | B16: ='PM Hypothetical assumptions'!B28 -> 150
A17: PM Hosted founder cash stipend · PM Monthly economics · Main Scenario | B17: ='PM Hypothetical assumptions'!B36 -> 1000
A18: PM Hosted founder cash stipend · Parity Medic · 100 customers | B18: ='PM Hypothetical assumptions'!B36 -> 1000
A19: PM Hosted founder cash stipend · Parity Medic · 500 customers | B19: ='PM Hypothetical assumptions'!B36 -> 1000
A20: PM Hosted growth experiments · PM Monthly economics · Main Scenario | B20: ='PM Hypothetical assumptions'!B38 -> 300
A21: PM Hosted growth experiments · Parity Medic · 100 customers | B21: ='PM Hypothetical assumptions'!B38 -> 300
A22: PM Hosted growth experiments · Parity Medic · 500 customers | B22: ='PM Hypothetical assumptions'!B38 -> 300
A23: PM Hosted individual compute storage · PM Monthly economics · Main Scenario | B23: ='PM Hypothetical assumptions'!B25 -> 0.75
A24: PM Hosted individual compute storage · Parity Medic · 100 customers | B24: ='PM Hypothetical assumptions'!B25 -> 0.75
A25: PM Hosted individual compute storage · Parity Medic · 500 customers | B25: ='PM Hypothetical assumptions'!B25 -> 0.75
A26: PM Hosted individual support hours · PM Monthly economics · Main Scenario | B26: ='PM Hypothetical assumptions'!B21 -> 0.15
A27: PM Hosted individual support hours · Parity Medic · 100 customers | B27: ='PM Hypothetical assumptions'!B21 -> 0.15
A28: PM Hosted individual support hours · Parity Medic · 500 customers | B28: ='PM Hypothetical assumptions'!B21 -> 0.15
A29: PM Hosted legal security reserve · PM Monthly economics · Main Scenario | B29: ='PM Hypothetical assumptions'!B32 -> 150
A30: PM Hosted legal security reserve · Parity Medic · 100 customers | B30: ='PM Hypothetical assumptions'!B32 -> 150
A31: PM Hosted legal security reserve · Parity Medic · 500 customers | B31: ='PM Hypothetical assumptions'!B32 -> 150
A32: PM Hosted monthly tax reserve · PM Monthly economics · Main Scenario | B32: =MAX(0,'Model inputs'!B155-'Model inputs'!B41)*'Model inputs'!B171 -> 0
A33: PM Hosted monthly tax reserve · PM Monthly economics · Parity Medic · 100 customers | B33: =MAX(0,'Model inputs'!B156-'Model inputs'!B42)*'Model inputs'!B188 -> 114.7
A34: PM Hosted monthly tax reserve · PM Monthly economics · Parity Medic · 500 customers | B34: =MAX(0,'Model inputs'!B157-'Model inputs'!B43)*'Model inputs'!B189 -> 1933.5
A35: PM Hosted net monthly burn · PM Monthly economics · Main Scenario | B35: ='Model inputs'!B149-'Model inputs'!B155 -> 1700
A36: PM Hosted net monthly burn · PM 12-month cash projection · Main Scenario | C36: ='Model inputs'!B149-'Model inputs'!B155 -> 1700
A37: PM Hosted net monthly burn · PM Monthly economics · Parity Medic · 100 customers | B37: ='Model inputs'!B150-'Model inputs'!B156 -> -458.8
A38: PM Hosted net monthly burn · PM 12-month cash projection · Parity Medic · 100 customers | C38: ='Model inputs'!B150-'Model inputs'!B156 -> -458.8
A39: PM Hosted net monthly burn · PM Monthly economics · Parity Medic · 500 customers | B39: ='Model inputs'!B151-'Model inputs'!B157 -> -7734
A40: PM Hosted net monthly burn · PM 12-month cash projection · Parity Medic · 500 customers | C40: ='Model inputs'!B151-'Model inputs'!B157 -> -7734
A41: PM Hosted pre-tax monthly cash cost · PM Monthly economics · Main Scenario | B41: ='Model inputs'!B168+'Model inputs'!B170+'Model inputs'!B169 -> 1700
...

Sheet Judging summary
A1: Accounts | B1: Delivery | C1: Monthly revenue USD | D1: Full monthly cost USD | E1: Net burn or surplus USD | F1: Runway months | G1: Economic profit USD
A2: 0 | B2: Local | C2: $0.00 | D2: $925.00 | E2: $925.00 | F2: 5.41 | G2: ($2,825.00)
A3: 0 | B3: Hosted | C3: $0.00 | D3: $1,700.00 | E3: $1,700.00 | F3: 2.94 | G3: ($3,200.00)
A4: 100 | B4: Local | C4: $3,500.00 | D4: $2,133.20 | E4: ($1,366.80) | F4: No finite limit | G4: ($533.20)
A5: 100 | B5: Hosted | C5: $3,500.00 | D5: $3,041.20 | E5: ($458.80) | F5: No finite limit | G5: ($1,041.20)
A6: 500 | B6: Local | C6: $17,500.00 | D6: $7,706.00 | E6: ($9,794.00) | F6: No finite limit | G6: $7,894.00
A7: 500 | B7: Hosted | C7: $17,500.00 | D7: $9,766.00 | E7: ($7,734.00) | F7: No finite limit | G7: $6,234.00

Sheet Repair cases
A1: Accounts | B1: Cost per repair USD | C1: Delivery | D1: Capped burn USD | E1: Capped runway months | F1: 100 repair burn USD | G1: 100 repair runway months
A2: 0 | B2: $0.05 | C2: Local | D2: $925.00 | E2: 5.41 | F2: $925.00 | G2: 5.41
A3: 0 | B3: $0.05 | C3: Hosted | D3: $1,700.00 | E3: 2.94 | F3: $1,700.00 | G3: 2.94
A4: 0 | B4: $0.25 | C4: Local | D4: $925.00 | E4: 5.41 | F4: $925.00 | G4: 5.41
A5: 0 | B5: $0.25 | C5: Hosted | D5: $1,700.00 | E5: 2.94 | F5: $1,700.00 | G5: 2.94
A6: 0 | B6: $1.00 | C6: Local | D6: $925.00 | E6: 5.41 | F6: $925.00 | G6: 5.41
A7: 0 | B7: $1.00 | C7: Hosted | D7: $1,700.00 | E7: 2.94 | F7: $1,700.00 | G7: 2.94
A8: 100 | B8: $0.05 | C8: Local | D8: ($1,366.80) | E8: No finite limit | F8: ($1,110.80) | G8: No finite limit
A9: 100 | B9: $0.05 | C9: Hosted | D9: ($458.80) | E9: No finite limit | F9: ($202.80) | G9: No finite limit
A10: 100 | B10: $0.25 | C10: Local | D10: ($790.80) | E10: No finite limit | F10: $611.50 | G10: 8.18
A11: 100 | B11: $0.25 | C11: Hosted | D11: $146.50 | E11: 34.13 | F11: $1,746.50 | G11: 2.86
A12: 100 | B12: $1.00 | C12: Local | D12: $1,711.50 | E12: 2.92 | F12: $8,111.50 | G12: 0.62
A13: 100 | B13: $1.00 | C13: Hosted | D13: $2,846.50 | E13: 1.76 | F13: $9,246.50 | G13: 0.54
... A19: 500 | B19: $1.00 | C19: Hosted | D19: $7,432.50 | E19: 0.67 | F19: $39,432.50 | G19: 0.13

Sheet Pricing cases
A1: Accounts | B1: Price factor | C1: ARPU USD | D1: Delivery | E1: Monthly burn USD | F1: Runway months
A2: 0 | B2: 75% | C2: $26.25 | D2: Local | E2: $925.00 | F2: 5.41
A3: 0 | B3: 75% | C3: $26.25 | D3: Hosted | E3: $1,700.00 | F3: 2.94
A4: 0 | B4: 100% | C4: $35.00 | D4: Local | E4: $925.00 | F4: 5.41
A5: 0 | B5: 100% | C5: $35.00 | D5: Hosted | E5: $1,700.00 | F5: 2.94
A6: 0 | B6: 125% | C6: $43.75 | D6: Local | E6: $925.00 | F6: 5.41
A7: 0 | B7: 125% | C7: $43.75 | D7: Hosted | E7: $1,700.00 | F7: 2.94
A8: 100 | B8: 75% | C8: $26.25 | D8: Local | E8: ($687.10) | F8: No finite limit
A9: 100 | B9: 75% | C9: $26.25 | D9: Hosted | E9: $276.12 | F9: 18.11
A10: 100 | B10: 100% | C10: $35.00 | D10: Local | E10: ($1,366.80) | F10: No finite limit
A11: 100 | B11: 100% | C11: $35.00 | D11: Hosted | E11: ($458.80) | F11: No finite limit
A12: 100 | B12: 125% | C12: $43.75 | D12: Local | E12: ($2,046.50) | F12: No finite limit
A13: 100 | B13: 125% | C13: $43.75 | D13: Hosted | E13: ($1,138.50) | F13: No finite limit
... A19: 500 | B19: 125% | C19: $43.75 | D19: Hosted | E19: ($11,132.50) | F19: No finite limit

Sheet Business plan
A1: # Parity Medic ## neatHack business plan · developer tools · USD **Decision:** validate a local-first verifier with paid, metered repair and evidence support. Do not build a broad hosted service or promise universal parity before proving demand and deployment safety.
A2: **Planning status:** new hypothetical project, unrelated to Rajendra Institute of Medical Sciences. No paying customers, funding, commercial launch, customer time savings or market size are verified. No existing company records or integrations were used or changed. Every commercial figure below is a proposal or hypothetical planning input. The $5,000 starting cash is a hypothetical budget, not a verified bank balance.
A3: ## 1. Product, buyer and evidence Parity Medic helps developers building agents and compatibility wrappers avoid silently changing an existing tool’s behavior. A developer supplies an adapter. The agent reads the original shipped implementation, tests revisions, and returns a measured result with supporting proof. The first reference is Bruno 4.2.1, limited to deterministic interpolation and JSON request preparation. It does not reconstruct arbitrary applications or send production requests.
A4: The initial buyer is a small developer-tool team maintaining wrappers around stable open-source tools. The proposed job-to-be-done is less manual mismatch investigation, a reproducible contract, and evidence that a particular revision preserves supported behavior. Positioning: **maintained reference contracts and credible, reproducible verification evidence—not “an agent that can clone anything.”**
A5: User-reported prototype evidence: one local repair improved 55/80 to 80/80, plus 80 independently chosen replay inputs. These reports were supplied in the planning brief; Ari did not inspect the repository or replay logs. Passing finite tests is not proof of universal parity, production safety or general customer impact. Do not combine the two sets into a claimed 160-test independent certification.
A6: The successful repair reportedly used three model calls and 28,418 tokens. Neatlogs estimated $0.0117204 for that trace; it is not a provider invoice and omits unsuccessful debugging attempts and hosting. The model uses a deliberately higher hypothetical $0.05 per repair, with $0.25 and $1.00 stress cases. Those planning values are not measured average repair costs.
